[2024-10-13 10:39:43,302] 97 werkzeug - INFO - [31m[1mWARNING: This is a development server. Do not use it in a production deployment. Use a production WSGI server instead.[0m
 * Running on http://127.0.0.1:5000
[2024-10-13 10:39:43,302] 97 werkzeug - INFO - [33mPress CTRL+C to quit[0m
[2024-10-13 10:39:49,349] 97 werkzeug - INFO - 127.0.0.1 - - [13/Oct/2024 10:39:49] "[33mGET /prediction/ HTTP/1.1[0m" 404 -
[2024-10-13 10:39:52,584] 838 app - ERROR - Exception on /prediction [GET]
Traceback (most recent call last):
  File "E:\Data_Science _master\ML\Diamonda_prediction\env\lib\site-packages\flask\app.py", line 1473, in wsgi_app
    response = self.full_dispatch_request()
  File "E:\Data_Science _master\ML\Diamonda_prediction\env\lib\site-packages\flask\app.py", line 882, in full_dispatch_request
    rv = self.handle_user_exception(e)
  File "E:\Data_Science _master\ML\Diamonda_prediction\env\lib\site-packages\flask\app.py", line 880, in full_dispatch_request
    rv = self.dispatch_request()
  File "E:\Data_Science _master\ML\Diamonda_prediction\env\lib\site-packages\flask\app.py", line 865, in dispatch_request
    return self.ensure_sync(self.view_functions[rule.endpoint])(**view_args)  # type: ignore[no-any-return]
  File "app.py", line 21, in predict_datapoint
    return render_template("form.html")
  File "E:\Data_Science _master\ML\Diamonda_prediction\env\lib\site-packages\flask\templating.py", line 150, in render_template
    return _render(app, template, context)
  File "E:\Data_Science _master\ML\Diamonda_prediction\env\lib\site-packages\flask\templating.py", line 131, in _render
    rv = template.render(context)
  File "E:\Data_Science _master\ML\Diamonda_prediction\env\lib\site-packages\jinja2\environment.py", line 1304, in render
    self.environment.handle_exception()
  File "E:\Data_Science _master\ML\Diamonda_prediction\env\lib\site-packages\jinja2\environment.py", line 939, in handle_exception
    raise rewrite_traceback_stack(source=source)
  File "E:\Data_Science _master\ML\Diamonda_prediction\templates\form.html", line 14, in top-level template code
    <form action="{{url_for('predict.datapoint')}}" method="POST">
  File "E:\Data_Science _master\ML\Diamonda_prediction\env\lib\site-packages\flask\app.py", line 1084, in url_for
    return self.handle_url_build_error(error, endpoint, values)
  File "E:\Data_Science _master\ML\Diamonda_prediction\env\lib\site-packages\flask\app.py", line 1073, in url_for
    rv = url_adapter.build(  # type: ignore[union-attr]
  File "E:\Data_Science _master\ML\Diamonda_prediction\env\lib\site-packages\werkzeug\routing\map.py", line 924, in build
    raise BuildError(endpoint, values, method, self)
werkzeug.routing.exceptions.BuildError: Could not build url for endpoint 'predict.datapoint'. Did you mean 'predict_datapoint' instead?
[2024-10-13 10:39:52,731] 97 werkzeug - INFO - 127.0.0.1 - - [13/Oct/2024 10:39:52] "[35m[1mGET /prediction HTTP/1.1[0m" 500 -
[2024-10-13 10:40:34,496] 838 app - ERROR - Exception on /prediction [GET]
Traceback (most recent call last):
  File "E:\Data_Science _master\ML\Diamonda_prediction\env\lib\site-packages\flask\app.py", line 1473, in wsgi_app
    response = self.full_dispatch_request()
  File "E:\Data_Science _master\ML\Diamonda_prediction\env\lib\site-packages\flask\app.py", line 882, in full_dispatch_request
    rv = self.handle_user_exception(e)
  File "E:\Data_Science _master\ML\Diamonda_prediction\env\lib\site-packages\flask\app.py", line 880, in full_dispatch_request
    rv = self.dispatch_request()
  File "E:\Data_Science _master\ML\Diamonda_prediction\env\lib\site-packages\flask\app.py", line 865, in dispatch_request
    return self.ensure_sync(self.view_functions[rule.endpoint])(**view_args)  # type: ignore[no-any-return]
  File "app.py", line 21, in predict_datapoint
    return render_template("form.html")
  File "E:\Data_Science _master\ML\Diamonda_prediction\env\lib\site-packages\flask\templating.py", line 150, in render_template
    return _render(app, template, context)
  File "E:\Data_Science _master\ML\Diamonda_prediction\env\lib\site-packages\flask\templating.py", line 131, in _render
    rv = template.render(context)
  File "E:\Data_Science _master\ML\Diamonda_prediction\env\lib\site-packages\jinja2\environment.py", line 1304, in render
    self.environment.handle_exception()
  File "E:\Data_Science _master\ML\Diamonda_prediction\env\lib\site-packages\jinja2\environment.py", line 939, in handle_exception
    raise rewrite_traceback_stack(source=source)
  File "E:\Data_Science _master\ML\Diamonda_prediction\templates\form.html", line 14, in top-level template code
  File "E:\Data_Science _master\ML\Diamonda_prediction\env\lib\site-packages\flask\app.py", line 1084, in url_for
    return self.handle_url_build_error(error, endpoint, values)
  File "E:\Data_Science _master\ML\Diamonda_prediction\env\lib\site-packages\flask\app.py", line 1073, in url_for
    rv = url_adapter.build(  # type: ignore[union-attr]
  File "E:\Data_Science _master\ML\Diamonda_prediction\env\lib\site-packages\werkzeug\routing\map.py", line 924, in build
    raise BuildError(endpoint, values, method, self)
werkzeug.routing.exceptions.BuildError: Could not build url for endpoint 'predict.datapoint'. Did you mean 'predict_datapoint' instead?
[2024-10-13 10:40:34,507] 97 werkzeug - INFO - 127.0.0.1 - - [13/Oct/2024 10:40:34] "[35m[1mGET /prediction HTTP/1.1[0m" 500 -
